<?xml version="1.0" ?>
<robot name="mobile_ai">
  <!-- trossen_black -->
  <!-- maple_tabletop -->
  <!-- wxai -->
  <material name="trossen_black">
    <texture filename="package://trossen_arm_description/meshes/trossen_black.png"/>
  </material>
  <!-- caster_wheel -->
  <link name="base_link">
    <inertial>
      <origin rpy="1.57079632679 0 0" xyz="0.01556204 0.00159774 0.22495608"/>
      <mass value="80"/>
      <inertia ixx="0.800607899578097" ixy="-0.000448278451746243" ixz="-1.46448934897976E-05" iyy="0.631097301133464" iyz="-1.76432150020805E-05" izz="0.560183616098452"/>
    </inertial>
    <visual>
      <origin rpy="-1.57079632679 0 0" xyz="0 0 0"/>
      <geometry>
        <mesh filename="package://trossen_arm_description/meshes/mobile_ai/base_link.dae"/>
      </geometry>
    </visual>
    <collision>
      <origin rpy="-1.57079632679 0 0" xyz="0 0 0"/>
      <geometry>
        <mesh filename="package://trossen_arm_description/meshes/mobile_ai/base_link.dae"/>
      </geometry>
    </collision>
  </link>
  <link name="base_footprint"/>
  <joint name="base_footprint_joint" type="fixed">
    <origin rpy="0 0 0" xyz="0 0 0.211"/>
    <parent link="base_footprint"/>
    <child link="base_link"/>
  </joint>
  <!-- camera body, with origin at bottom screw mount -->
  <joint name="cam_high_joint" type="fixed">
    <origin rpy="0 0.6457718232379019 0" xyz="0.209805 0 1.031778"/>
    <parent link="base_link"/>
    <child link="cam_high_bottom_screw_frame"/>
  </joint>
  <link name="cam_high_bottom_screw_frame"/>
  <joint name="cam_high_link_joint" type="fixed">
    <origin rpy="0 0 0" xyz="0.01085 0.009 0.021"/>
    <parent link="cam_high_bottom_screw_frame"/>
    <child link="cam_high_link"/>
  </joint>
  <link name="cam_high_link">
    <visual>
      <!-- the mesh origin is at front plate in between the two infrared camera axes -->
      <origin rpy="1.5707963267948966 0 1.5707963267948966" xyz="0.0038 -0.009 0"/>
      <geometry>
        <mesh filename="package://trossen_arm_description/meshes/peripherals/d405.stl" scale="0.001 0.001 0.001"/>
      </geometry>
      <material name="aluminum">
        <color rgba="0.5 0.5 0.5 1"/>
      </material>
    </visual>
    <collision>
      <origin rpy="0 0 0" xyz="-0.0078 -0.009 0"/>
      <geometry>
        <box size="0.023 0.042 0.042"/>
      </geometry>
    </collision>
    <inertial>
      <!-- The following are not reliable values, and should not be used for modeling -->
      <mass value="0.072"/>
      <origin xyz="0 0 0"/>
      <inertia ixx="0.00002117" ixy="0.0" ixz="0.0" iyy="0.000013758" iyz="0.0" izz="0.000013758"/>
    </inertial>
  </link>
  <!-- camera depth joints and links -->
  <joint name="cam_high_depth_joint" type="fixed">
    <origin rpy="0 0 0" xyz="0 0 0"/>
    <parent link="cam_high_link"/>
    <child link="cam_high_depth_frame"/>
  </joint>
  <link name="cam_high_depth_frame"/>
  <joint name="cam_high_depth_optical_joint" type="fixed">
    <origin rpy="-1.5707963267948966 0 -1.5707963267948966" xyz="0 0 0"/>
    <parent link="cam_high_depth_frame"/>
    <child link="cam_high_depth_optical_frame"/>
  </joint>
  <link name="cam_high_depth_optical_frame"/>
  <!-- camera left IR joints and links -->
  <joint name="cam_high_infra1_joint" type="fixed">
    <origin rpy="0 0 0" xyz="0 0.0 0"/>
    <parent link="cam_high_link"/>
    <child link="cam_high_infra1_frame"/>
  </joint>
  <link name="cam_high_infra1_frame"/>
  <joint name="cam_high_infra1_optical_joint" type="fixed">
    <origin rpy="-1.5707963267948966 0 -1.5707963267948966" xyz="0 0 0"/>
    <parent link="cam_high_infra1_frame"/>
    <child link="cam_high_infra1_optical_frame"/>
  </joint>
  <link name="cam_high_infra1_optical_frame"/>
  <!-- camera right IR joints and links -->
  <joint name="cam_high_infra2_joint" type="fixed">
    <origin rpy="0 0 0" xyz="0 -0.018 0"/>
    <parent link="cam_high_link"/>
    <child link="cam_high_infra2_frame"/>
  </joint>
  <link name="cam_high_infra2_frame"/>
  <joint name="cam_high_infra2_optical_joint" type="fixed">
    <origin rpy="-1.5707963267948966 0 -1.5707963267948966" xyz="0 0 0"/>
    <parent link="cam_high_infra2_frame"/>
    <child link="cam_high_infra2_optical_frame"/>
  </joint>
  <link name="cam_high_infra2_optical_frame"/>
  <!-- camera color joints and links -->
  <joint name="cam_high_color_joint" type="fixed">
    <origin rpy="0 0 0" xyz="0 0.0 0"/>
    <parent link="cam_high_link"/>
    <child link="cam_high_color_frame"/>
  </joint>
  <link name="cam_high_color_frame"/>
  <joint name="cam_high_color_optical_joint" type="fixed">
    <origin rpy="-1.5707963267948966 0 -1.5707963267948966" xyz="0 0 0"/>
    <parent link="cam_high_color_frame"/>
    <child link="cam_high_color_optical_frame"/>
  </joint>
  <link name="cam_high_color_optical_frame"/>
  <joint name="left_wheel" type="continuous">
    <origin rpy="0 0 0" xyz="0 0.192 -0.1259 "/>
    <parent link="base_link"/>
    <child link="left_wheel_link"/>
    <axis xyz="0 1 0"/>
    <limit effort="4" velocity="12.566370614359172"/>
  </joint>
  <link name="left_wheel_link">
    <inertial>
      <origin rpy="0 0 0" xyz="0 0 0"/>
      <mass value="3.00000000"/>
      <inertia ixx="0.00165792997375718" ixy="4.41844662675169E-36" ixz="2.2697691956304E-36" iyy="0.00291162000439156" iyz="-7.2280144832367E-21" izz="0.00165792997375718"/>
    </inertial>
    <visual>
      <origin rpy="0 0 0" xyz="0 0 0"/>
      <geometry>
        <mesh filename="package://trossen_arm_description/meshes/mobile_ai/wheel.stl"/>
      </geometry>
      <material name="">
        <color rgba="0.792156862745098 0.819607843137255 0.933333333333333 1"/>
      </material>
    </visual>
    <collision>
      <origin rpy="0 0 0" xyz="0 0 0"/>
      <geometry>
        <mesh filename="package://trossen_arm_description/meshes/mobile_ai/wheel.stl"/>
      </geometry>
    </collision>
  </link>
  <joint name="right_wheel" type="continuous">
    <origin rpy="0 0 0" xyz="0 -0.192 -0.1259"/>
    <parent link="base_link"/>
    <child link="right_wheel_link"/>
    <axis xyz="0 1 0"/>
    <limit effort="4" velocity="12.566370614359172"/>
  </joint>
  <link name="right_wheel_link">
    <inertial>
      <origin rpy="0 0 0" xyz="0 0 0"/>
      <mass value="3.00000000"/>
      <inertia ixx="0.00165792997375718" ixy="4.41844662675169E-36" ixz="2.2697691956304E-36" iyy="0.00291162000439156" iyz="-7.22801448323669E-21" izz="0.00165792997375718"/>
    </inertial>
    <visual>
      <origin rpy="0 0 0" xyz="0 0 0"/>
      <geometry>
        <mesh filename="package://trossen_arm_description/meshes/mobile_ai/wheel.stl"/>
      </geometry>
      <material name="">
        <color rgba="0.792156862745098 0.819607843137255 0.933333333333333 1"/>
      </material>
    </visual>
    <collision>
      <origin rpy="0 0 0" xyz="0 0 0"/>
      <geometry>
        <mesh filename="package://trossen_arm_description/meshes/mobile_ai/wheel.stl"/>
      </geometry>
    </collision>
  </link>
  <link name="caster_swivel_front_left">
    <inertial>
      <origin rpy="0 0 0" xyz="-0.00642926 0 -0.02324376"/>
      <mass value="0.10000000"/>
      <inertia ixx="3.29304410034736E-05" ixy="-1.39762576137236E-21" ixz="7.8716764062508E-06" iyy="3.55223730522351E-05" iyz="-3.5017225502273E-21" izz="2.57879736183465E-05"/>
    </inertial>
    <visual>
      <origin rpy="0 0 0" xyz="0 0 0"/>
      <geometry>
        <mesh filename="package://trossen_arm_description/meshes/mobile_ai/caster_swivel.stl"/>
      </geometry>
      <material name="">
        <color rgba="0.792156862745098 0.819607843137255 0.933333333333333 1"/>
      </material>
    </visual>
    <collision>
      <origin rpy="0 0 0" xyz="0 0 0"/>
      <geometry>
        <mesh filename="package://trossen_arm_description/meshes/mobile_ai/caster_swivel.stl"/>
      </geometry>
    </collision>
  </link>
  <joint name="caster_swivel_joint_front_left" type="continuous">
    <origin rpy="0 0 0" xyz="0.168 0.17 -0.107"/>
    <parent link="base_link"/>
    <child link="caster_swivel_front_left"/>
    <axis xyz="0 0 1"/>
    <limit effort="0" velocity="3.141592653589793"/>
  </joint>
  <link name="caster_wheel_front_left">
    <inertial>
      <origin rpy="0 0 0" xyz="0 0 0"/>
      <mass value="0.53500000"/>
      <inertia ixx="3.50667612783944E-05" ixy="5.20590616718454E-38" ixz="7.13705176187339E-53" iyy="6.42430517058348E-05" iyz="1.20456076700477E-37" izz="3.50667612783944E-05"/>
    </inertial>
    <visual>
      <origin rpy="0 0 0" xyz="0 0 0"/>
      <geometry>
        <mesh filename="package://trossen_arm_description/meshes/mobile_ai/caster_wheel.stl"/>
      </geometry>
      <material name="">
        <color rgba="0.792156862745098 0.819607843137255 0.933333333333333 1"/>
      </material>
    </visual>
    <collision>
      <origin rpy="0 0 0" xyz="0 0 0"/>
      <geometry>
        <mesh filename="package://trossen_arm_description/meshes/mobile_ai/caster_wheel.stl"/>
      </geometry>
    </collision>
  </link>
  <joint name="caster_wheel_joint_front_left" type="continuous">
    <origin rpy="0 0 0" xyz="-0.0345 0 -0.066"/>
    <parent link="caster_swivel_front_left"/>
    <child link="caster_wheel_front_left"/>
    <axis xyz="0 1 0"/>
    <limit effort="0" velocity="3.141592653589793"/>
  </joint>
  <link name="caster_swivel_front_right">
    <inertial>
      <origin rpy="0 0 0" xyz="-0.00642926 0 -0.02324376"/>
      <mass value="0.10000000"/>
      <inertia ixx="3.29304410034736E-05" ixy="-1.39762576137236E-21" ixz="7.8716764062508E-06" iyy="3.55223730522351E-05" iyz="-3.5017225502273E-21" izz="2.57879736183465E-05"/>
    </inertial>
    <visual>
      <origin rpy="0 0 0" xyz="0 0 0"/>
      <geometry>
        <mesh filename="package://trossen_arm_description/meshes/mobile_ai/caster_swivel.stl"/>
      </geometry>
      <material name="">
        <color rgba="0.792156862745098 0.819607843137255 0.933333333333333 1"/>
      </material>
    </visual>
    <collision>
      <origin rpy="0 0 0" xyz="0 0 0"/>
      <geometry>
        <mesh filename="package://trossen_arm_description/meshes/mobile_ai/caster_swivel.stl"/>
      </geometry>
    </collision>
  </link>
  <joint name="caster_swivel_joint_front_right" type="continuous">
    <origin rpy="0 0 0" xyz="0.16843 -0.17 -0.107"/>
    <parent link="base_link"/>
    <child link="caster_swivel_front_right"/>
    <axis xyz="0 0 1"/>
    <limit effort="0" velocity="3.141592653589793"/>
  </joint>
  <link name="caster_wheel_front_right">
    <inertial>
      <origin rpy="0 0 0" xyz="0 0 0"/>
      <mass value="0.53500000"/>
      <inertia ixx="3.50667612783944E-05" ixy="5.20590616718454E-38" ixz="7.13705176187339E-53" iyy="6.42430517058348E-05" iyz="1.20456076700477E-37" izz="3.50667612783944E-05"/>
    </inertial>
    <visual>
      <origin rpy="0 0 0" xyz="0 0 0"/>
      <geometry>
        <mesh filename="package://trossen_arm_description/meshes/mobile_ai/caster_wheel.stl"/>
      </geometry>
      <material name="">
        <color rgba="0.792156862745098 0.819607843137255 0.933333333333333 1"/>
      </material>
    </visual>
    <collision>
      <origin rpy="0 0 0" xyz="0 0 0"/>
      <geometry>
        <mesh filename="package://trossen_arm_description/meshes/mobile_ai/caster_wheel.stl"/>
      </geometry>
    </collision>
  </link>
  <joint name="caster_wheel_joint_front_right" type="continuous">
    <origin rpy="0 0 0" xyz="-0.0345 0 -0.066"/>
    <parent link="caster_swivel_front_right"/>
    <child link="caster_wheel_front_right"/>
    <axis xyz="0 1 0"/>
    <limit effort="0" velocity="3.141592653589793"/>
  </joint>
  <link name="caster_swivel_rear_left">
    <inertial>
      <origin rpy="0 0 0" xyz="-0.00642926 0 -0.02324376"/>
      <mass value="0.10000000"/>
      <inertia ixx="3.29304410034736E-05" ixy="-1.39762576137236E-21" ixz="7.8716764062508E-06" iyy="3.55223730522351E-05" iyz="-3.5017225502273E-21" izz="2.57879736183465E-05"/>
    </inertial>
    <visual>
      <origin rpy="0 0 0" xyz="0 0 0"/>
      <geometry>
        <mesh filename="package://trossen_arm_description/meshes/mobile_ai/caster_swivel.stl"/>
      </geometry>
      <material name="">
        <color rgba="0.792156862745098 0.819607843137255 0.933333333333333 1"/>
      </material>
    </visual>
    <collision>
      <origin rpy="0 0 0" xyz="0 0 0"/>
      <geometry>
        <mesh filename="package://trossen_arm_description/meshes/mobile_ai/caster_swivel.stl"/>
      </geometry>
    </collision>
  </link>
  <joint name="caster_swivel_joint_rear_left" type="continuous">
    <origin rpy="0 0 0" xyz="-0.16783 0.17 -0.107"/>
    <parent link="base_link"/>
    <child link="caster_swivel_rear_left"/>
    <axis xyz="0 0 1"/>
    <limit effort="0" velocity="3.141592653589793"/>
  </joint>
  <link name="caster_wheel_rear_left">
    <inertial>
      <origin rpy="0 0 0" xyz="0 0 0"/>
      <mass value="0.53500000"/>
      <inertia ixx="3.50667612783944E-05" ixy="5.20590616718454E-38" ixz="7.13705176187339E-53" iyy="6.42430517058348E-05" iyz="1.20456076700477E-37" izz="3.50667612783944E-05"/>
    </inertial>
    <visual>
      <origin rpy="0 0 0" xyz="0 0 0"/>
      <geometry>
        <mesh filename="package://trossen_arm_description/meshes/mobile_ai/caster_wheel.stl"/>
      </geometry>
      <material name="">
        <color rgba="0.792156862745098 0.819607843137255 0.933333333333333 1"/>
      </material>
    </visual>
    <collision>
      <origin rpy="0 0 0" xyz="0 0 0"/>
      <geometry>
        <mesh filename="package://trossen_arm_description/meshes/mobile_ai/caster_wheel.stl"/>
      </geometry>
    </collision>
  </link>
  <joint name="caster_wheel_joint_rear_left" type="continuous">
    <origin rpy="0 0 0" xyz="-0.0345 0 -0.066"/>
    <parent link="caster_swivel_rear_left"/>
    <child link="caster_wheel_rear_left"/>
    <axis xyz="0 1 0"/>
    <limit effort="0" velocity="3.141592653589793"/>
  </joint>
  <link name="caster_swivel_rear_right">
    <inertial>
      <origin rpy="0 0 0" xyz="-0.00642926 0 -0.02324376"/>
      <mass value="0.10000000"/>
      <inertia ixx="3.29304410034736E-05" ixy="-1.39762576137236E-21" ixz="7.8716764062508E-06" iyy="3.55223730522351E-05" iyz="-3.5017225502273E-21" izz="2.57879736183465E-05"/>
    </inertial>
    <visual>
      <origin rpy="0 0 0" xyz="0 0 0"/>
      <geometry>
        <mesh filename="package://trossen_arm_description/meshes/mobile_ai/caster_swivel.stl"/>
      </geometry>
      <material name="">
        <color rgba="0.792156862745098 0.819607843137255 0.933333333333333 1"/>
      </material>
    </visual>
    <collision>
      <origin rpy="0 0 0" xyz="0 0 0"/>
      <geometry>
        <mesh filename="package://trossen_arm_description/meshes/mobile_ai/caster_swivel.stl"/>
      </geometry>
    </collision>
  </link>
  <joint name="caster_swivel_joint_rear_right" type="continuous">
    <origin rpy="0 0 0" xyz="-0.168 -0.17 -0.107"/>
    <parent link="base_link"/>
    <child link="caster_swivel_rear_right"/>
    <axis xyz="0 0 1"/>
    <limit effort="0" velocity="3.141592653589793"/>
  </joint>
  <link name="caster_wheel_rear_right">
    <inertial>
      <origin rpy="0 0 0" xyz="0 0 0"/>
      <mass value="0.53500000"/>
      <inertia ixx="3.50667612783944E-05" ixy="5.20590616718454E-38" ixz="7.13705176187339E-53" iyy="6.42430517058348E-05" iyz="1.20456076700477E-37" izz="3.50667612783944E-05"/>
    </inertial>
    <visual>
      <origin rpy="0 0 0" xyz="0 0 0"/>
      <geometry>
        <mesh filename="package://trossen_arm_description/meshes/mobile_ai/caster_wheel.stl"/>
      </geometry>
      <material name="">
        <color rgba="0.792156862745098 0.819607843137255 0.933333333333333 1"/>
      </material>
    </visual>
    <collision>
      <origin rpy="0 0 0" xyz="0 0 0"/>
      <geometry>
        <mesh filename="package://trossen_arm_description/meshes/mobile_ai/caster_wheel.stl"/>
      </geometry>
    </collision>
  </link>
  <joint name="caster_wheel_joint_rear_right" type="continuous">
    <origin rpy="0 0 0" xyz="-0.0345 0 -0.066"/>
    <parent link="caster_swivel_rear_right"/>
    <child link="caster_wheel_rear_right"/>
    <axis xyz="0 1 0"/>
    <limit effort="0" velocity="3.141592653589793"/>
  </joint>
  <joint name="follower_left_mount_joint" type="fixed">
    <origin rpy="0 0 0" xyz="0.331 0.3 0.831"/>
    <parent link="base_link"/>
    <child link="follower_left_base_link"/>
  </joint>
  <ros2_control name="TrossenArmHardwareInterface" type="system">
    <hardware>
      <plugin>mock_components/GenericSystem</plugin>
      <!-- ros2_control_hardware_type == 'mock_components' -->
      <!-- ros2_control_hardware_type == 'real' -->
    </hardware>
    <joint name="follower_left_joint_0">
      <command_interface name="position"/>
      <command_interface name="velocity"/>
      <command_interface name="external_effort"/>
      <state_interface name="position">
        <param name="initial_value">0.0</param>
      </state_interface>
      <state_interface name="velocity">
        <param name="initial_value">0.0</param>
      </state_interface>
      <state_interface name="effort">
        <param name="initial_value">0.0</param>
      </state_interface>
    </joint>
    <joint name="follower_left_joint_1">
      <command_interface name="position"/>
      <command_interface name="velocity"/>
      <command_interface name="external_effort"/>
      <state_interface name="position">
        <param name="initial_value">0.0</param>
      </state_interface>
      <state_interface name="velocity">
        <param name="initial_value">0.0</param>
      </state_interface>
      <state_interface name="effort">
        <param name="initial_value">0.0</param>
      </state_interface>
    </joint>
    <joint name="follower_left_joint_2">
      <command_interface name="position"/>
      <command_interface name="velocity"/>
      <command_interface name="external_effort"/>
      <state_interface name="position">
        <param name="initial_value">0.0</param>
      </state_interface>
      <state_interface name="velocity">
        <param name="initial_value">0.0</param>
      </state_interface>
      <state_interface name="effort">
        <param name="initial_value">0.0</param>
      </state_interface>
    </joint>
    <joint name="follower_left_joint_3">
      <command_interface name="position"/>
      <command_interface name="velocity"/>
      <command_interface name="external_effort"/>
      <state_interface name="position">
        <param name="initial_value">0.0</param>
      </state_interface>
      <state_interface name="velocity">
        <param name="initial_value">0.0</param>
      </state_interface>
      <state_interface name="effort">
        <param name="initial_value">0.0</param>
      </state_interface>
    </joint>
    <joint name="follower_left_joint_4">
      <command_interface name="position"/>
      <command_interface name="velocity"/>
      <command_interface name="external_effort"/>
      <state_interface name="position">
        <param name="initial_value">0.0</param>
      </state_interface>
      <state_interface name="velocity">
        <param name="initial_value">0.0</param>
      </state_interface>
      <state_interface name="effort">
        <param name="initial_value">0.0</param>
      </state_interface>
    </joint>
    <joint name="follower_left_joint_5">
      <command_interface name="position"/>
      <command_interface name="velocity"/>
      <command_interface name="external_effort"/>
      <state_interface name="position">
        <param name="initial_value">0.0</param>
      </state_interface>
      <state_interface name="velocity">
        <param name="initial_value">0.0</param>
      </state_interface>
      <state_interface name="effort">
        <param name="initial_value">0.0</param>
      </state_interface>
    </joint>
    <joint name="follower_left_left_carriage_joint">
      <command_interface name="position"/>
      <command_interface name="velocity"/>
      <command_interface name="external_effort"/>
      <state_interface name="position">
        <param name="initial_value">0.0</param>
      </state_interface>
      <state_interface name="velocity">
        <param name="initial_value">0.0</param>
      </state_interface>
      <state_interface name="effort">
        <param name="initial_value">0.0</param>
      </state_interface>
    </joint>
  </ros2_control>
  <link name="follower_left_base_link">
    <inertial>
      <origin rpy="0 0 0" xyz="-0.00014175 -0.00005228 0.03175177"/>
      <mass value="0.45969858"/>
      <inertia ixx="0.00041660" ixy="0.00000011" ixz="-0.00000454" iyy="0.00044896" iyz="-0.00000078" izz="0.00021403"/>
    </inertial>
    <visual>
      <origin rpy="0 0 0" xyz="0 0 0"/>
      <geometry>
        <mesh filename="package://trossen_arm_description/meshes/wxai/base_link.stl"/>
      </geometry>
      <material name="trossen_black"/>
    </visual>
    <collision>
      <origin rpy="0 0 0" xyz="0 0 0"/>
      <geometry>
        <mesh filename="package://trossen_arm_description/meshes/wxai/base_link.stl"/>
      </geometry>
    </collision>
  </link>
  <link name="follower_left_link_1">
    <inertial>
      <origin rpy="0 0 0" xyz="-0.00011075 0.00171176 0.02044592"/>
      <mass value="0.15270428"/>
      <inertia ixx="0.00018509" ixy="-0.00000191" ixz="-0.00001436" iyy="0.00008358" iyz="-0.00000130" izz="0.00019219"/>
    </inertial>
    <visual>
      <origin rpy="0 0 0" xyz="0 0 0"/>
      <geometry>
        <mesh filename="package://trossen_arm_description/meshes/wxai/link_1.stl"/>
      </geometry>
      <material name="trossen_black"/>
    </visual>
    <collision>
      <origin rpy="0 0 0" xyz="0 0 0"/>
      <geometry>
        <mesh filename="package://trossen_arm_description/meshes/wxai/link_1.stl"/>
      </geometry>
    </collision>
  </link>
  <joint name="follower_left_joint_0" type="revolute">
    <origin rpy="0 0 0" xyz="0 0 0.05725"/>
    <parent link="follower_left_base_link"/>
    <child link="follower_left_link_1"/>
    <axis xyz="0 0 1"/>
    <limit effort="27.0" lower="-3.0543261909900767" upper="3.0543261909900767" velocity="3.375"/>
  </joint>
  <link name="follower_left_link_2">
    <inertial>
      <origin rpy="0 0 0" xyz="-0.13121451 -0.00292583 0.00021345"/>
      <mass value="1.15316319"/>
      <inertia ixx="0.00102632" ixy="-0.00000319" ixz="-0.00002679" iyy="0.01736118" iyz="-0.00000193" izz="0.01794489"/>
    </inertial>
    <visual>
      <origin rpy="0 0 0" xyz="0 0 0"/>
      <geometry>
        <mesh filename="package://trossen_arm_description/meshes/wxai/link_2.stl"/>
      </geometry>
      <material name="trossen_black"/>
    </visual>
    <collision>
      <origin rpy="0 0 0" xyz="0 0 0"/>
      <geometry>
        <mesh filename="package://trossen_arm_description/meshes/wxai/link_2.stl"/>
      </geometry>
    </collision>
  </link>
  <joint name="follower_left_joint_1" type="revolute">
    <origin rpy="0 0 0" xyz="0.02 0 0.04625"/>
    <parent link="follower_left_link_1"/>
    <child link="follower_left_link_2"/>
    <axis xyz="0 1 0"/>
    <limit effort="27.0" lower="0.0" upper="3.141592653589793" velocity="3.375"/>
  </joint>
  <link name="follower_left_link_3">
    <inertial>
      <origin rpy="0 0 0" xyz="0.18083602 -0.00094090 0.05554937"/>
      <mass value="0.68666638"/>
      <inertia ixx="0.00064876" ixy="0.00009128" ixz="-0.00052002" iyy="0.00547407" iyz="0.00001159" izz="0.00561509"/>
    </inertial>
    <visual>
      <origin rpy="0 0 0" xyz="0 0 0"/>
      <geometry>
        <mesh filename="package://trossen_arm_description/meshes/wxai/link_3.stl"/>
      </geometry>
      <material name="trossen_black"/>
    </visual>
    <collision>
      <origin rpy="0 0 0" xyz="0 0 0"/>
      <geometry>
        <mesh filename="package://trossen_arm_description/meshes/wxai/link_3.stl"/>
      </geometry>
    </collision>
  </link>
  <joint name="follower_left_joint_2" type="revolute">
    <origin rpy="0 0 0" xyz="-0.264 0 0"/>
    <parent link="follower_left_link_2"/>
    <child link="follower_left_link_3"/>
    <axis xyz="0 -1 0"/>
    <limit effort="27.0" lower="0.0" upper="2.356194490192345" velocity="3.375"/>
  </joint>
  <link name="follower_left_link_4">
    <inertial>
      <origin rpy="0 0 0" xyz="0.05797842 0.00027145 0.05884447"/>
      <mass value="0.45789905"/>
      <inertia ixx="0.00053839" ixy="0.00000690" ixz="-0.00018164" iyy="0.00066138" iyz="0.00000724" izz="0.00042116"/>
    </inertial>
    <visual>
      <origin rpy="0 0 0" xyz="0 0 0"/>
      <geometry>
        <mesh filename="package://trossen_arm_description/meshes/wxai/link_4.stl"/>
      </geometry>
      <material name="trossen_black"/>
    </visual>
    <collision>
      <origin rpy="0 0 0" xyz="0 0 0"/>
      <geometry>
        <mesh filename="package://trossen_arm_description/meshes/wxai/link_4.stl"/>
      </geometry>
    </collision>
  </link>
  <joint name="follower_left_joint_3" type="revolute">
    <origin rpy="0 0 0" xyz="0.245 0 0.06"/>
    <parent link="follower_left_link_3"/>
    <child link="follower_left_link_4"/>
    <axis xyz="0 -1 0"/>
    <limit effort="7.0" lower="-1.5707963267948966" upper="1.5707963267948966" velocity="7.0"/>
  </joint>
  <link name="follower_left_link_5">
    <inertial>
      <origin rpy="0 0 0" xyz="0.00412447 -0.00001138 -0.04283184"/>
      <mass value="0.36693910"/>
      <inertia ixx="0.00018912" ixy="-0.00000045" ixz="0.00000090" iyy="0.00032062" iyz="0.00000003" izz="0.00026750"/>
    </inertial>
    <visual>
      <origin rpy="0 0 0" xyz="0 0 0"/>
      <geometry>
        <mesh filename="package://trossen_arm_description/meshes/wxai/link_5.stl"/>
      </geometry>
      <material name="trossen_black"/>
    </visual>
    <collision>
      <origin rpy="0 0 0" xyz="0 0 0"/>
      <geometry>
        <mesh filename="package://trossen_arm_description/meshes/wxai/link_5.stl"/>
      </geometry>
    </collision>
  </link>
  <joint name="follower_left_joint_4" type="revolute">
    <origin rpy="0 0 0" xyz="0.06775 0 0.0455"/>
    <parent link="follower_left_link_4"/>
    <child link="follower_left_link_5"/>
    <axis xyz="0 0 -1"/>
    <limit effort="7.0" lower="-1.5707963267948966" upper="1.5707963267948966" velocity="7.0"/>
  </joint>
  <link name="follower_left_link_6">
    <inertial>
      <origin rpy="0 0 0" xyz="0.04572768 -0.00000726 0.00001402"/>
      <mass value="0.55469347"/>
      <inertia ixx="0.00082429" ixy="-0.00000051" ixz="0.00000010" iyy="0.00048759" iyz="0.00000004" izz="0.00108600"/>
    </inertial>
    <visual>
      <origin rpy="0 0 0" xyz="0 0 0"/>
      <geometry>
        <mesh filename="package://trossen_arm_description/meshes/wxai/link_6.stl"/>
      </geometry>
      <material name="trossen_black"/>
    </visual>
    <collision>
      <origin rpy="0 0 0" xyz="0 0 0"/>
      <geometry>
        <mesh filename="package://trossen_arm_description/meshes/wxai/link_6.stl"/>
      </geometry>
    </collision>
  </link>
  <joint name="follower_left_joint_5" type="revolute">
    <origin rpy="0 0 0" xyz="0.02895 0 -0.0455"/>
    <parent link="follower_left_link_5"/>
    <child link="follower_left_link_6"/>
    <axis xyz="1 0 0"/>
    <limit effort="7.0" lower="-3.141592653589793" upper="3.141592653589793" velocity="7.0"/>
  </joint>
  <link name="follower_left_carriage_right">
    <inertial>
      <origin rpy="0 0 0" xyz="-0.00889602 0.00403514 0.00457901"/>
      <mass value="0.05036313"/>
      <inertia ixx="0.00001736" ixy="-0.00000165" ixz="-0.00000104" iyy="0.00000591" iyz="-0.00000172" izz="0.00001378"/>
    </inertial>
    <visual>
      <origin rpy="0 0 0" xyz="0 0 0"/>
      <geometry>
        <mesh filename="package://trossen_arm_description/meshes/wxai/carriage_right.stl"/>
      </geometry>
      <material name="trossen_black"/>
    </visual>
    <collision>
      <origin rpy="0 0 0" xyz="0 0 0"/>
      <geometry>
        <mesh filename="package://trossen_arm_description/meshes/wxai/carriage_right.stl"/>
      </geometry>
    </collision>
  </link>
  <joint name="follower_left_right_carriage_joint" type="prismatic">
    <origin rpy="0 0 0" xyz="0.0865 -0.023 0"/>
    <parent link="follower_left_link_6"/>
    <child link="follower_left_carriage_right"/>
    <mimic joint="follower_left_left_carriage_joint"/>
    <axis xyz="0 -1 0"/>
    <limit effort="400.0" lower="0.0" upper="0.044" velocity="0.0875"/>
  </joint>
  <link name="follower_left_carriage_left">
    <inertial>
      <origin rpy="0 0 0" xyz="-0.00889602 -0.00403515 -0.00457908"/>
      <mass value="0.05036313"/>
      <inertia ixx="0.00001736" ixy="-0.00000165" ixz="-0.00000104" iyy="0.00000591" iyz="-0.00000172" izz="0.00001378"/>
    </inertial>
    <visual>
      <origin rpy="0 0 0" xyz="0 0 0"/>
      <geometry>
        <mesh filename="package://trossen_arm_description/meshes/wxai/carriage_left.stl"/>
      </geometry>
      <material name="trossen_black"/>
    </visual>
    <collision>
      <origin rpy="0 0 0" xyz="0 0 0"/>
      <geometry>
        <mesh filename="package://trossen_arm_description/meshes/wxai/carriage_left.stl"/>
      </geometry>
    </collision>
  </link>
  <joint name="follower_left_left_carriage_joint" type="prismatic">
    <origin rpy="0 0 0" xyz="0.0865 0.023 0"/>
    <parent link="follower_left_link_6"/>
    <child link="follower_left_carriage_left"/>
    <axis xyz="0 1 0"/>
    <limit effort="400.0" lower="0.0" upper="0.044" velocity="0.0875"/>
  </joint>
  <link name="follower_left_camera_mount_d405">
    <inertial>
      <origin rpy="0 0 0" xyz="0.03023383 0.00679835 0.05006687"/>
      <mass value="0.04518012"/>
      <inertia ixx="0.00003426" ixy="-0.00000027" ixz="-0.00000309" iyy="0.00001980" iyz="-0.00000319" izz="0.00002470"/>
    </inertial>
    <visual>
      <origin rpy="0 0 0" xyz="0 0 0"/>
      <geometry>
        <mesh filename="package://trossen_arm_description/meshes/wxai/camera_mount_d405.stl"/>
      </geometry>
      <material name="trossen_black"/>
    </visual>
    <collision>
      <origin rpy="0 0 0" xyz="0 0 0"/>
      <geometry>
        <mesh filename="package://trossen_arm_description/meshes/wxai/camera_mount_d405.stl"/>
      </geometry>
    </collision>
  </link>
  <joint name="follower_left_camera_mount_joint" type="fixed">
    <origin rpy="0 0 0" xyz="0.012 0 0"/>
    <parent link="follower_left_link_6"/>
    <child link="follower_left_camera_mount_d405"/>
  </joint>
  <!-- camera body, with origin at bottom screw mount -->
  <joint name="follower_left_camera_joint" type="fixed">
    <origin rpy="0 0.3490658503988659 0" xyz="0.02927207801 0 0.03824951197"/>
    <parent link="follower_left_camera_mount_d405"/>
    <child link="follower_left_camera_bottom_screw_frame"/>
  </joint>
  <link name="follower_left_camera_bottom_screw_frame"/>
  <joint name="follower_left_camera_link_joint" type="fixed">
    <origin rpy="0 0 0" xyz="0.01085 0.009 0.021"/>
    <parent link="follower_left_camera_bottom_screw_frame"/>
    <child link="follower_left_camera_link"/>
  </joint>
  <link name="follower_left_camera_link">
    <visual>
      <!-- the mesh origin is at front plate in between the two infrared camera axes -->
      <origin rpy="1.5707963267948966 0 1.5707963267948966" xyz="0.0038 -0.009 0"/>
      <geometry>
        <mesh filename="package://trossen_arm_description/meshes/peripherals/d405.stl" scale="0.001 0.001 0.001"/>
      </geometry>
      <material name="aluminum">
        <color rgba="0.5 0.5 0.5 1"/>
      </material>
    </visual>
    <collision>
      <origin rpy="0 0 0" xyz="-0.0078 -0.009 0"/>
      <geometry>
        <box size="0.023 0.042 0.042"/>
      </geometry>
    </collision>
    <inertial>
      <!-- The following are not reliable values, and should not be used for modeling -->
      <mass value="0.072"/>
      <origin xyz="0 0 0"/>
      <inertia ixx="0.00002117" ixy="0.0" ixz="0.0" iyy="0.000013758" iyz="0.0" izz="0.000013758"/>
    </inertial>
  </link>
  <!-- camera depth joints and links -->
  <joint name="follower_left_camera_depth_joint" type="fixed">
    <origin rpy="0 0 0" xyz="0 0 0"/>
    <parent link="follower_left_camera_link"/>
    <child link="follower_left_camera_depth_frame"/>
  </joint>
  <link name="follower_left_camera_depth_frame"/>
  <joint name="follower_left_camera_depth_optical_joint" type="fixed">
    <origin rpy="-1.5707963267948966 0 -1.5707963267948966" xyz="0 0 0"/>
    <parent link="follower_left_camera_depth_frame"/>
    <child link="follower_left_camera_depth_optical_frame"/>
  </joint>
  <link name="follower_left_camera_depth_optical_frame"/>
  <!-- camera left IR joints and links -->
  <joint name="follower_left_camera_infra1_joint" type="fixed">
    <origin rpy="0 0 0" xyz="0 0.0 0"/>
    <parent link="follower_left_camera_link"/>
    <child link="follower_left_camera_infra1_frame"/>
  </joint>
  <link name="follower_left_camera_infra1_frame"/>
  <joint name="follower_left_camera_infra1_optical_joint" type="fixed">
    <origin rpy="-1.5707963267948966 0 -1.5707963267948966" xyz="0 0 0"/>
    <parent link="follower_left_camera_infra1_frame"/>
    <child link="follower_left_camera_infra1_optical_frame"/>
  </joint>
  <link name="follower_left_camera_infra1_optical_frame"/>
  <!-- camera right IR joints and links -->
  <joint name="follower_left_camera_infra2_joint" type="fixed">
    <origin rpy="0 0 0" xyz="0 -0.018 0"/>
    <parent link="follower_left_camera_link"/>
    <child link="follower_left_camera_infra2_frame"/>
  </joint>
  <link name="follower_left_camera_infra2_frame"/>
  <joint name="follower_left_camera_infra2_optical_joint" type="fixed">
    <origin rpy="-1.5707963267948966 0 -1.5707963267948966" xyz="0 0 0"/>
    <parent link="follower_left_camera_infra2_frame"/>
    <child link="follower_left_camera_infra2_optical_frame"/>
  </joint>
  <link name="follower_left_camera_infra2_optical_frame"/>
  <!-- camera color joints and links -->
  <joint name="follower_left_camera_color_joint" type="fixed">
    <origin rpy="0 0 0" xyz="0 0.0 0"/>
    <parent link="follower_left_camera_link"/>
    <child link="follower_left_camera_color_frame"/>
  </joint>
  <link name="follower_left_camera_color_frame"/>
  <joint name="follower_left_camera_color_optical_joint" type="fixed">
    <origin rpy="-1.5707963267948966 0 -1.5707963267948966" xyz="0 0 0"/>
    <parent link="follower_left_camera_color_frame"/>
    <child link="follower_left_camera_color_optical_frame"/>
  </joint>
  <link name="follower_left_camera_color_optical_frame"/>
  <!-- variant == 'follower' -->
  <!-- variant == 'leader' -->
  <link name="follower_left_gripper_left">
    <inertial>
      <origin rpy="0 0 0" xyz="0.01893993 -0.00901223 -0.00215453"/>
      <mass value="0.03090787"/>
      <inertia ixx="0.00000769" ixy="0.00000321" ixz="0.00000029" iyy="0.00001487" iyz="-0.00000020" izz="0.00001184"/>
    </inertial>
    <visual>
      <origin rpy="0 0 0" xyz="0 0 0"/>
      <geometry>
        <mesh filename="package://trossen_arm_description/meshes/wxai/gripper_left.stl"/>
      </geometry>
      <material name="trossen_black"/>
    </visual>
    <collision>
      <origin rpy="0 0 0" xyz="0 0 0"/>
      <geometry>
        <mesh filename="package://trossen_arm_description/meshes/wxai/gripper_left.stl"/>
      </geometry>
    </collision>
  </link>
  <joint name="follower_left_left_gripper_joint" type="fixed">
    <origin rpy="0 0 0" xyz="0 0 0"/>
    <parent link="follower_left_carriage_left"/>
    <child link="follower_left_gripper_left"/>
  </joint>
  <link name="follower_left_gripper_right">
    <inertial>
      <origin rpy="0 0 0" xyz="0.01893989 0.00901216 -0.00215461"/>
      <mass value="0.03090786"/>
      <inertia ixx="0.00000769" ixy="-0.00000321" ixz="0.00000029" iyy="0.00001487" iyz="0.00000020" izz="0.00001184"/>
    </inertial>
    <visual>
      <origin rpy="0 0 0" xyz="0 0 0"/>
      <geometry>
        <mesh filename="package://trossen_arm_description/meshes/wxai/gripper_right.stl"/>
      </geometry>
      <material name="trossen_black"/>
    </visual>
    <collision>
      <origin rpy="0 0 0" xyz="0 0 0"/>
      <geometry>
        <mesh filename="package://trossen_arm_description/meshes/wxai/gripper_right.stl"/>
      </geometry>
    </collision>
  </link>
  <joint name="follower_left_right_gripper_joint" type="fixed">
    <origin rpy="0 0 0" xyz="0 0 0"/>
    <parent link="follower_left_carriage_right"/>
    <child link="follower_left_gripper_right"/>
  </joint>
  <joint name="follower_left_ee_gripper" type="fixed">
    <origin rpy="0 0 0" xyz="0.156062 0 0"/>
    <parent link="follower_left_link_6"/>
    <child link="follower_left_ee_gripper_link"/>
  </joint>
  <link name="follower_left_ee_gripper_link"/>
  <!-- variant in ('base', 'follower') -->
  <joint name="follower_right_mount_joint" type="fixed">
    <origin rpy="0 0 0" xyz="0.331 -0.3 0.831"/>
    <parent link="base_link"/>
    <child link="follower_right_base_link"/>
  </joint>
  <ros2_control name="TrossenArmHardwareInterface" type="system">
    <hardware>
      <plugin>mock_components/GenericSystem</plugin>
      <!-- ros2_control_hardware_type == 'mock_components' -->
      <!-- ros2_control_hardware_type == 'real' -->
    </hardware>
    <joint name="follower_right_joint_0">
      <command_interface name="position"/>
      <command_interface name="velocity"/>
      <command_interface name="external_effort"/>
      <state_interface name="position">
        <param name="initial_value">0.0</param>
      </state_interface>
      <state_interface name="velocity">
        <param name="initial_value">0.0</param>
      </state_interface>
      <state_interface name="effort">
        <param name="initial_value">0.0</param>
      </state_interface>
    </joint>
    <joint name="follower_right_joint_1">
      <command_interface name="position"/>
      <command_interface name="velocity"/>
      <command_interface name="external_effort"/>
      <state_interface name="position">
        <param name="initial_value">0.0</param>
      </state_interface>
      <state_interface name="velocity">
        <param name="initial_value">0.0</param>
      </state_interface>
      <state_interface name="effort">
        <param name="initial_value">0.0</param>
      </state_interface>
    </joint>
    <joint name="follower_right_joint_2">
      <command_interface name="position"/>
      <command_interface name="velocity"/>
      <command_interface name="external_effort"/>
      <state_interface name="position">
        <param name="initial_value">0.0</param>
      </state_interface>
      <state_interface name="velocity">
        <param name="initial_value">0.0</param>
      </state_interface>
      <state_interface name="effort">
        <param name="initial_value">0.0</param>
      </state_interface>
    </joint>
    <joint name="follower_right_joint_3">
      <command_interface name="position"/>
      <command_interface name="velocity"/>
      <command_interface name="external_effort"/>
      <state_interface name="position">
        <param name="initial_value">0.0</param>
      </state_interface>
      <state_interface name="velocity">
        <param name="initial_value">0.0</param>
      </state_interface>
      <state_interface name="effort">
        <param name="initial_value">0.0</param>
      </state_interface>
    </joint>
    <joint name="follower_right_joint_4">
      <command_interface name="position"/>
      <command_interface name="velocity"/>
      <command_interface name="external_effort"/>
      <state_interface name="position">
        <param name="initial_value">0.0</param>
      </state_interface>
      <state_interface name="velocity">
        <param name="initial_value">0.0</param>
      </state_interface>
      <state_interface name="effort">
        <param name="initial_value">0.0</param>
      </state_interface>
    </joint>
    <joint name="follower_right_joint_5">
      <command_interface name="position"/>
      <command_interface name="velocity"/>
      <command_interface name="external_effort"/>
      <state_interface name="position">
        <param name="initial_value">0.0</param>
      </state_interface>
      <state_interface name="velocity">
        <param name="initial_value">0.0</param>
      </state_interface>
      <state_interface name="effort">
        <param name="initial_value">0.0</param>
      </state_interface>
    </joint>
    <joint name="follower_right_left_carriage_joint">
      <command_interface name="position"/>
      <command_interface name="velocity"/>
      <command_interface name="external_effort"/>
      <state_interface name="position">
        <param name="initial_value">0.0</param>
      </state_interface>
      <state_interface name="velocity">
        <param name="initial_value">0.0</param>
      </state_interface>
      <state_interface name="effort">
        <param name="initial_value">0.0</param>
      </state_interface>
    </joint>
  </ros2_control>
  <link name="follower_right_base_link">
    <inertial>
      <origin rpy="0 0 0" xyz="-0.00014175 -0.00005228 0.03175177"/>
      <mass value="0.45969858"/>
      <inertia ixx="0.00041660" ixy="0.00000011" ixz="-0.00000454" iyy="0.00044896" iyz="-0.00000078" izz="0.00021403"/>
    </inertial>
    <visual>
      <origin rpy="0 0 0" xyz="0 0 0"/>
      <geometry>
        <mesh filename="package://trossen_arm_description/meshes/wxai/base_link.stl"/>
      </geometry>
      <material name="trossen_black"/>
    </visual>
    <collision>
      <origin rpy="0 0 0" xyz="0 0 0"/>
      <geometry>
        <mesh filename="package://trossen_arm_description/meshes/wxai/base_link.stl"/>
      </geometry>
    </collision>
  </link>
  <link name="follower_right_link_1">
    <inertial>
      <origin rpy="0 0 0" xyz="-0.00011075 0.00171176 0.02044592"/>
      <mass value="0.15270428"/>
      <inertia ixx="0.00018509" ixy="-0.00000191" ixz="-0.00001436" iyy="0.00008358" iyz="-0.00000130" izz="0.00019219"/>
    </inertial>
    <visual>
      <origin rpy="0 0 0" xyz="0 0 0"/>
      <geometry>
        <mesh filename="package://trossen_arm_description/meshes/wxai/link_1.stl"/>
      </geometry>
      <material name="trossen_black"/>
    </visual>
    <collision>
      <origin rpy="0 0 0" xyz="0 0 0"/>
      <geometry>
        <mesh filename="package://trossen_arm_description/meshes/wxai/link_1.stl"/>
      </geometry>
    </collision>
  </link>
  <joint name="follower_right_joint_0" type="revolute">
    <origin rpy="0 0 0" xyz="0 0 0.05725"/>
    <parent link="follower_right_base_link"/>
    <child link="follower_right_link_1"/>
    <axis xyz="0 0 1"/>
    <limit effort="27.0" lower="-3.0543261909900767" upper="3.0543261909900767" velocity="3.375"/>
  </joint>
  <link name="follower_right_link_2">
    <inertial>
      <origin rpy="0 0 0" xyz="-0.13121451 -0.00292583 0.00021345"/>
      <mass value="1.15316319"/>
      <inertia ixx="0.00102632" ixy="-0.00000319" ixz="-0.00002679" iyy="0.01736118" iyz="-0.00000193" izz="0.01794489"/>
    </inertial>
    <visual>
      <origin rpy="0 0 0" xyz="0 0 0"/>
      <geometry>
        <mesh filename="package://trossen_arm_description/meshes/wxai/link_2.stl"/>
      </geometry>
      <material name="trossen_black"/>
    </visual>
    <collision>
      <origin rpy="0 0 0" xyz="0 0 0"/>
      <geometry>
        <mesh filename="package://trossen_arm_description/meshes/wxai/link_2.stl"/>
      </geometry>
    </collision>
  </link>
  <joint name="follower_right_joint_1" type="revolute">
    <origin rpy="0 0 0" xyz="0.02 0 0.04625"/>
    <parent link="follower_right_link_1"/>
    <child link="follower_right_link_2"/>
    <axis xyz="0 1 0"/>
    <limit effort="27.0" lower="0.0" upper="3.141592653589793" velocity="3.375"/>
  </joint>
  <link name="follower_right_link_3">
    <inertial>
      <origin rpy="0 0 0" xyz="0.18083602 -0.00094090 0.05554937"/>
      <mass value="0.68666638"/>
      <inertia ixx="0.00064876" ixy="0.00009128" ixz="-0.00052002" iyy="0.00547407" iyz="0.00001159" izz="0.00561509"/>
    </inertial>
    <visual>
      <origin rpy="0 0 0" xyz="0 0 0"/>
      <geometry>
        <mesh filename="package://trossen_arm_description/meshes/wxai/link_3.stl"/>
      </geometry>
      <material name="trossen_black"/>
    </visual>
    <collision>
      <origin rpy="0 0 0" xyz="0 0 0"/>
      <geometry>
        <mesh filename="package://trossen_arm_description/meshes/wxai/link_3.stl"/>
      </geometry>
    </collision>
  </link>
  <joint name="follower_right_joint_2" type="revolute">
    <origin rpy="0 0 0" xyz="-0.264 0 0"/>
    <parent link="follower_right_link_2"/>
    <child link="follower_right_link_3"/>
    <axis xyz="0 -1 0"/>
    <limit effort="27.0" lower="0.0" upper="2.356194490192345" velocity="3.375"/>
  </joint>
  <link name="follower_right_link_4">
    <inertial>
      <origin rpy="0 0 0" xyz="0.05797842 0.00027145 0.05884447"/>
      <mass value="0.45789905"/>
      <inertia ixx="0.00053839" ixy="0.00000690" ixz="-0.00018164" iyy="0.00066138" iyz="0.00000724" izz="0.00042116"/>
    </inertial>
    <visual>
      <origin rpy="0 0 0" xyz="0 0 0"/>
      <geometry>
        <mesh filename="package://trossen_arm_description/meshes/wxai/link_4.stl"/>
      </geometry>
      <material name="trossen_black"/>
    </visual>
    <collision>
      <origin rpy="0 0 0" xyz="0 0 0"/>
      <geometry>
        <mesh filename="package://trossen_arm_description/meshes/wxai/link_4.stl"/>
      </geometry>
    </collision>
  </link>
  <joint name="follower_right_joint_3" type="revolute">
    <origin rpy="0 0 0" xyz="0.245 0 0.06"/>
    <parent link="follower_right_link_3"/>
    <child link="follower_right_link_4"/>
    <axis xyz="0 -1 0"/>
    <limit effort="7.0" lower="-1.5707963267948966" upper="1.5707963267948966" velocity="7.0"/>
  </joint>
  <link name="follower_right_link_5">
    <inertial>
      <origin rpy="0 0 0" xyz="0.00412447 -0.00001138 -0.04283184"/>
      <mass value="0.36693910"/>
      <inertia ixx="0.00018912" ixy="-0.00000045" ixz="0.00000090" iyy="0.00032062" iyz="0.00000003" izz="0.00026750"/>
    </inertial>
    <visual>
      <origin rpy="0 0 0" xyz="0 0 0"/>
      <geometry>
        <mesh filename="package://trossen_arm_description/meshes/wxai/link_5.stl"/>
      </geometry>
      <material name="trossen_black"/>
    </visual>
    <collision>
      <origin rpy="0 0 0" xyz="0 0 0"/>
      <geometry>
        <mesh filename="package://trossen_arm_description/meshes/wxai/link_5.stl"/>
      </geometry>
    </collision>
  </link>
  <joint name="follower_right_joint_4" type="revolute">
    <origin rpy="0 0 0" xyz="0.06775 0 0.0455"/>
    <parent link="follower_right_link_4"/>
    <child link="follower_right_link_5"/>
    <axis xyz="0 0 -1"/>
    <limit effort="7.0" lower="-1.5707963267948966" upper="1.5707963267948966" velocity="7.0"/>
  </joint>
  <link name="follower_right_link_6">
    <inertial>
      <origin rpy="0 0 0" xyz="0.04572768 -0.00000726 0.00001402"/>
      <mass value="0.55469347"/>
      <inertia ixx="0.00082429" ixy="-0.00000051" ixz="0.00000010" iyy="0.00048759" iyz="0.00000004" izz="0.00108600"/>
    </inertial>
    <visual>
      <origin rpy="0 0 0" xyz="0 0 0"/>
      <geometry>
        <mesh filename="package://trossen_arm_description/meshes/wxai/link_6.stl"/>
      </geometry>
      <material name="trossen_black"/>
    </visual>
    <collision>
      <origin rpy="0 0 0" xyz="0 0 0"/>
      <geometry>
        <mesh filename="package://trossen_arm_description/meshes/wxai/link_6.stl"/>
      </geometry>
    </collision>
  </link>
  <joint name="follower_right_joint_5" type="revolute">
    <origin rpy="0 0 0" xyz="0.02895 0 -0.0455"/>
    <parent link="follower_right_link_5"/>
    <child link="follower_right_link_6"/>
    <axis xyz="1 0 0"/>
    <limit effort="7.0" lower="-3.141592653589793" upper="3.141592653589793" velocity="7.0"/>
  </joint>
  <link name="follower_right_carriage_right">
    <inertial>
      <origin rpy="0 0 0" xyz="-0.00889602 0.00403514 0.00457901"/>
      <mass value="0.05036313"/>
      <inertia ixx="0.00001736" ixy="-0.00000165" ixz="-0.00000104" iyy="0.00000591" iyz="-0.00000172" izz="0.00001378"/>
    </inertial>
    <visual>
      <origin rpy="0 0 0" xyz="0 0 0"/>
      <geometry>
        <mesh filename="package://trossen_arm_description/meshes/wxai/carriage_right.stl"/>
      </geometry>
      <material name="trossen_black"/>
    </visual>
    <collision>
      <origin rpy="0 0 0" xyz="0 0 0"/>
      <geometry>
        <mesh filename="package://trossen_arm_description/meshes/wxai/carriage_right.stl"/>
      </geometry>
    </collision>
  </link>
  <joint name="follower_right_right_carriage_joint" type="prismatic">
    <origin rpy="0 0 0" xyz="0.0865 -0.023 0"/>
    <parent link="follower_right_link_6"/>
    <child link="follower_right_carriage_right"/>
    <mimic joint="follower_right_left_carriage_joint"/>
    <axis xyz="0 -1 0"/>
    <limit effort="400.0" lower="0.0" upper="0.044" velocity="0.0875"/>
  </joint>
  <link name="follower_right_carriage_left">
    <inertial>
      <origin rpy="0 0 0" xyz="-0.00889602 -0.00403515 -0.00457908"/>
      <mass value="0.05036313"/>
      <inertia ixx="0.00001736" ixy="-0.00000165" ixz="-0.00000104" iyy="0.00000591" iyz="-0.00000172" izz="0.00001378"/>
    </inertial>
    <visual>
      <origin rpy="0 0 0" xyz="0 0 0"/>
      <geometry>
        <mesh filename="package://trossen_arm_description/meshes/wxai/carriage_left.stl"/>
      </geometry>
      <material name="trossen_black"/>
    </visual>
    <collision>
      <origin rpy="0 0 0" xyz="0 0 0"/>
      <geometry>
        <mesh filename="package://trossen_arm_description/meshes/wxai/carriage_left.stl"/>
      </geometry>
    </collision>
  </link>
  <joint name="follower_right_left_carriage_joint" type="prismatic">
    <origin rpy="0 0 0" xyz="0.0865 0.023 0"/>
    <parent link="follower_right_link_6"/>
    <child link="follower_right_carriage_left"/>
    <axis xyz="0 1 0"/>
    <limit effort="400.0" lower="0.0" upper="0.044" velocity="0.0875"/>
  </joint>
  <link name="follower_right_camera_mount_d405">
    <inertial>
      <origin rpy="0 0 0" xyz="0.03023383 0.00679835 0.05006687"/>
      <mass value="0.04518012"/>
      <inertia ixx="0.00003426" ixy="-0.00000027" ixz="-0.00000309" iyy="0.00001980" iyz="-0.00000319" izz="0.00002470"/>
    </inertial>
    <visual>
      <origin rpy="0 0 0" xyz="0 0 0"/>
      <geometry>
        <mesh filename="package://trossen_arm_description/meshes/wxai/camera_mount_d405.stl"/>
      </geometry>
      <material name="trossen_black"/>
    </visual>
    <collision>
      <origin rpy="0 0 0" xyz="0 0 0"/>
      <geometry>
        <mesh filename="package://trossen_arm_description/meshes/wxai/camera_mount_d405.stl"/>
      </geometry>
    </collision>
  </link>
  <joint name="follower_right_camera_mount_joint" type="fixed">
    <origin rpy="0 0 0" xyz="0.012 0 0"/>
    <parent link="follower_right_link_6"/>
    <child link="follower_right_camera_mount_d405"/>
  </joint>
  <!-- camera body, with origin at bottom screw mount -->
  <joint name="follower_right_camera_joint" type="fixed">
    <origin rpy="0 0.3490658503988659 0" xyz="0.02927207801 0 0.03824951197"/>
    <parent link="follower_right_camera_mount_d405"/>
    <child link="follower_right_camera_bottom_screw_frame"/>
  </joint>
  <link name="follower_right_camera_bottom_screw_frame"/>
  <joint name="follower_right_camera_link_joint" type="fixed">
    <origin rpy="0 0 0" xyz="0.01085 0.009 0.021"/>
    <parent link="follower_right_camera_bottom_screw_frame"/>
    <child link="follower_right_camera_link"/>
  </joint>
  <link name="follower_right_camera_link">
    <visual>
      <!-- the mesh origin is at front plate in between the two infrared camera axes -->
      <origin rpy="1.5707963267948966 0 1.5707963267948966" xyz="0.0038 -0.009 0"/>
      <geometry>
        <mesh filename="package://trossen_arm_description/meshes/peripherals/d405.stl" scale="0.001 0.001 0.001"/>
      </geometry>
      <material name="aluminum">
        <color rgba="0.5 0.5 0.5 1"/>
      </material>
    </visual>
    <collision>
      <origin rpy="0 0 0" xyz="-0.0078 -0.009 0"/>
      <geometry>
        <box size="0.023 0.042 0.042"/>
      </geometry>
    </collision>
    <inertial>
      <!-- The following are not reliable values, and should not be used for modeling -->
      <mass value="0.072"/>
      <origin xyz="0 0 0"/>
      <inertia ixx="0.00002117" ixy="0.0" ixz="0.0" iyy="0.000013758" iyz="0.0" izz="0.000013758"/>
    </inertial>
  </link>
  <!-- camera depth joints and links -->
  <joint name="follower_right_camera_depth_joint" type="fixed">
    <origin rpy="0 0 0" xyz="0 0 0"/>
    <parent link="follower_right_camera_link"/>
    <child link="follower_right_camera_depth_frame"/>
  </joint>
  <link name="follower_right_camera_depth_frame"/>
  <joint name="follower_right_camera_depth_optical_joint" type="fixed">
    <origin rpy="-1.5707963267948966 0 -1.5707963267948966" xyz="0 0 0"/>
    <parent link="follower_right_camera_depth_frame"/>
    <child link="follower_right_camera_depth_optical_frame"/>
  </joint>
  <link name="follower_right_camera_depth_optical_frame"/>
  <!-- camera left IR joints and links -->
  <joint name="follower_right_camera_infra1_joint" type="fixed">
    <origin rpy="0 0 0" xyz="0 0.0 0"/>
    <parent link="follower_right_camera_link"/>
    <child link="follower_right_camera_infra1_frame"/>
  </joint>
  <link name="follower_right_camera_infra1_frame"/>
  <joint name="follower_right_camera_infra1_optical_joint" type="fixed">
    <origin rpy="-1.5707963267948966 0 -1.5707963267948966" xyz="0 0 0"/>
    <parent link="follower_right_camera_infra1_frame"/>
    <child link="follower_right_camera_infra1_optical_frame"/>
  </joint>
  <link name="follower_right_camera_infra1_optical_frame"/>
  <!-- camera right IR joints and links -->
  <joint name="follower_right_camera_infra2_joint" type="fixed">
    <origin rpy="0 0 0" xyz="0 -0.018 0"/>
    <parent link="follower_right_camera_link"/>
    <child link="follower_right_camera_infra2_frame"/>
  </joint>
  <link name="follower_right_camera_infra2_frame"/>
  <joint name="follower_right_camera_infra2_optical_joint" type="fixed">
    <origin rpy="-1.5707963267948966 0 -1.5707963267948966" xyz="0 0 0"/>
    <parent link="follower_right_camera_infra2_frame"/>
    <child link="follower_right_camera_infra2_optical_frame"/>
  </joint>
  <link name="follower_right_camera_infra2_optical_frame"/>
  <!-- camera color joints and links -->
  <joint name="follower_right_camera_color_joint" type="fixed">
    <origin rpy="0 0 0" xyz="0 0.0 0"/>
    <parent link="follower_right_camera_link"/>
    <child link="follower_right_camera_color_frame"/>
  </joint>
  <link name="follower_right_camera_color_frame"/>
  <joint name="follower_right_camera_color_optical_joint" type="fixed">
    <origin rpy="-1.5707963267948966 0 -1.5707963267948966" xyz="0 0 0"/>
    <parent link="follower_right_camera_color_frame"/>
    <child link="follower_right_camera_color_optical_frame"/>
  </joint>
  <link name="follower_right_camera_color_optical_frame"/>
  <!-- variant == 'follower' -->
  <!-- variant == 'leader' -->
  <link name="follower_right_gripper_left">
    <inertial>
      <origin rpy="0 0 0" xyz="0.01893993 -0.00901223 -0.00215453"/>
      <mass value="0.03090787"/>
      <inertia ixx="0.00000769" ixy="0.00000321" ixz="0.00000029" iyy="0.00001487" iyz="-0.00000020" izz="0.00001184"/>
    </inertial>
    <visual>
      <origin rpy="0 0 0" xyz="0 0 0"/>
      <geometry>
        <mesh filename="package://trossen_arm_description/meshes/wxai/gripper_left.stl"/>
      </geometry>
      <material name="trossen_black"/>
    </visual>
    <collision>
      <origin rpy="0 0 0" xyz="0 0 0"/>
      <geometry>
        <mesh filename="package://trossen_arm_description/meshes/wxai/gripper_left.stl"/>
      </geometry>
    </collision>
  </link>
  <joint name="follower_right_left_gripper_joint" type="fixed">
    <origin rpy="0 0 0" xyz="0 0 0"/>
    <parent link="follower_right_carriage_left"/>
    <child link="follower_right_gripper_left"/>
  </joint>
  <link name="follower_right_gripper_right">
    <inertial>
      <origin rpy="0 0 0" xyz="0.01893989 0.00901216 -0.00215461"/>
      <mass value="0.03090786"/>
      <inertia ixx="0.00000769" ixy="-0.00000321" ixz="0.00000029" iyy="0.00001487" iyz="0.00000020" izz="0.00001184"/>
    </inertial>
    <visual>
      <origin rpy="0 0 0" xyz="0 0 0"/>
      <geometry>
        <mesh filename="package://trossen_arm_description/meshes/wxai/gripper_right.stl"/>
      </geometry>
      <material name="trossen_black"/>
    </visual>
    <collision>
      <origin rpy="0 0 0" xyz="0 0 0"/>
      <geometry>
        <mesh filename="package://trossen_arm_description/meshes/wxai/gripper_right.stl"/>
      </geometry>
    </collision>
  </link>
  <joint name="follower_right_right_gripper_joint" type="fixed">
    <origin rpy="0 0 0" xyz="0 0 0"/>
    <parent link="follower_right_carriage_right"/>
    <child link="follower_right_gripper_right"/>
  </joint>
  <joint name="follower_right_ee_gripper" type="fixed">
    <origin rpy="0 0 0" xyz="0.156062 0 0"/>
    <parent link="follower_right_link_6"/>
    <child link="follower_right_ee_gripper_link"/>
  </joint>
  <link name="follower_right_ee_gripper_link"/>
  <!-- variant in ('base', 'follower') -->
</robot>
